<robot name="unnamed">

  <material name="green">
  <color rgba="0 1 0 1"/>
  </material>

  <material name="grey">
  <color rgba="0.1 0.1 0.1 1"/>
  </material>

  <link name="base_link">
    <visual>
      <origin rpy="0 0 1.57" xyz="0 0 0.0508"/>
      <geometry>
        <mesh filename="package://unnamed_toaster/meshes/unnamed_toaster_frame.stl"/>
      </geometry>
    </visual>
  </link>

  <joint name="base_link_to_laser" type="fixed">
    <parent link="base_link"/>
    <child link="laser"/>
    <origin xyz="-0.193675 0.09525 0.2" rpy="0 0 1.57"/>
  </joint>

  <link name="laser">
    <visual>
      <origin rpy="0 0 0" xyz="0 0 0"/>
      <geometry>
        <cylinder length="0.1016" radius="0.0508"/>
      </geometry>
    <material name="grey"/>
    </visual>
  </link>
  
  <joint name="turret_joint" type="revolute">
    <axis xyz="0 0 1"/>
    <limit effort="1000.0" lower="-6.0" upper="6.0" velocity="0.5"/>
    <parent link="base_link"/>
    <child link="turret"/>
    <origin xyz="-0.0922782 0.0 0.263525" rpy="0.0 0.0 0.0"/>
  </joint>

  <link name="turret">
    <visual>
      <origin xyz="0.0 0.0 0.0" rpy="0.0 0.0 1.57"/>
      <geometry>
        <mesh filename="package://unnamed_toaster/meshes/unnamed_toaster_turret.stl"/>
      </geometry>
    <material name="grey"/>
    </visual>
  </link>

  <joint name="turret_to_limelight" type="fixed">
    <parent link="turret"/>
    <child link="limelight"/>
    <origin xyz="0.0 0.2428875 0.4318" rpy="0.0 0.0 0.0"/>
  </joint>

  <link name="limelight">
    <visual>
      <origin xyz="0.0 0.0 0.0" rpy="0 0 0"/>
      <geometry>
        <box size="0.0254 0.09779 0.05715 "/>
      </geometry>
      <material name="green"/>
    </visual>
  </link>
</robot>
